Workbook

Sheet Detallado de la inversión.
C4: Zonix Pharma — Marketplace farmacéutico VE (piloto Valencia)
C8: Descripción
E9: Cant.
C10: CONSTITUCIÓN DE LA EMPRESA (Zonix Pharma C.A.) | F10: USD/u | K10: RESUMEN INVERSIÓN LEAN (v3.9.1)
C11: Registro Mercantil + acta constitutiva | E11: 1 | F11: 1200 | G11: =E11*F11 -> 1200 | H11: =IF(G11=0,"",G11/G109) -> 0.010715434 | K11: One-shots (legal+intro+HQ) | M11: =G76 -> 14208
C12: SENIAT — inscripción / trámites RIF | E12: 1 | F12: 600 | G12: =E12*F12 -> 600 | H12: =IF(G12=0,"",G12/G109) -> 0.0053577169 | K12: Fase 0 operativa (sin one-shots) | M12: =G78 -> 17377
C13: Licencia / permisos municipales HQ | E13: 1 | F13: 1500 | G13: =E13*F13 -> 1500 | H13: =IF(G13=0,"",G13/G109) -> 0.013394292 | I13: Notas / En ESTA | K13: Fase 0 total (T+0→Day-D) | M13: =G72 -> 33835
C14: Permiso bomberos (local operativo) | E14: 1 | F14: 1100 | G14: =E14*F14 -> 1100 | H14: =IF(G14=0,"",G14/G109) -> 0.009822481 | K14: Caja al Day-D (inicio M1) | M14: =G74 -> 78153
C15: Apertura cuenta bancaria empresa | E15: 1 | F15: 100 | G15: =E15*F15 -> 100 | H15: =IF(G15=0,"",G15/G109) -> 0.00089295282 | K15: Burn 12 meses (M1–M12) | M15: =G107 -> 97290
C16: Sello digital + factura digital SENIAT | E16: 1 | F16: 200 | G16: =E16*F16 -> 200 | H16: =IF(G16=0,"",G16/G109) -> 0.0017859056 | K16: Reserva caja | M16: =G108 -> 490
C17: Registro marca SAPI (paralelo) | E17: 1 | F17: 350 | G17: =E17*F17 -> 350 | H17: =IF(G17=0,"",G17/G109) -> 0.0031253349 | K17: TOTAL capital SAFE | M17: =G109 -> 111988
C18: Subtotal constitución empresa | G18: =SUM(G11:G17) -> 5050 | H18: =IF(G18=0,"",G18/G109) -> 0.045094117 | K18: SAFE cap ref. → ~18.66% equity | M18: =M17/600000 -> 0.18664667
C20: Costos legales de constitución C.A. + local HQ (referencia real VE). No incluye permisos de farmacia aliada ni operación de medicamentos. Pack documental conservador 1.150–1.450 en ESTRUCTURA_LEGAL §1.4 — validar con abogado [PENDIENTE]. | K20: Ref. mensual post-Day-D
K21: MO operativa (subtotal) | M21: =G90 -> 5155
C22: MATERIA PRIMA: No aplica — ZonixPharma es servicio tecnológico (marketplace). Equivalente digital: SMS OTP, Pusher, Maps, hosting → fila «Hosting + SaaS + Firebase OTP» en ESTA SI VALE (~154 USD/mes) + contingencia en burn. | K22: Marketing mensual (subtotal) | M22: =G103 -> 2953
K23: Incluido en burn M1–M12. No sumar a one-shots ni duplicar MO Fase 0. Unit economics → pestaña ESTA SI VALE.
C24: INTRODUCCIÓN AL MERCADO / DEMO — Lean (ancla Fase 0)
C25: Website landing + dominio | E25: 1 | F25: 800 | G25: =E25*F25 -> 800 | H25: =IF(G25=0,"",G25/G109) -> 0.0071436225
C26: Brochures y material impreso B2B | E26: 1 | F26: 400 | G26: =E26*F26 -> 400 | H26: =IF(G26=0,"",G26/G109) -> 0.0035718113
C27: Tablets demo farmacia | E27: 2 | F27: 350 | G27: =E27*F27 -> 700 | H27: =IF(G27=0,"",G27/G109) -> 0.0062506697
C28: Visitas comerciales pre-Day-D | E28: 1 | F28: 500 | G28: =E28*F28 -> 500 | H28: =IF(G28=0,"",G28/G109) -> 0.0044647641
C29: Reservas operativas primer mes | E29: 1 | F29: 608 | G29: =E29*F29 -> 608 | H29: =IF(G29=0,"",G29/G109) -> 0.0054291531
C30: Video pitch B2B farmacia (one-shot) | E30: 1 | F30: 800 | G30: =E30*F30 -> 800 | H30: =IF(G30=0,"",G30/G109) -> 0.0071436225
C31: Subtotal intro mercado Lean | G31: =SUM(G25:G30) -> 3808 | H31: =IF(G31=0,"",G31/G109) -> 0.034003643
C33: MARKETING PRE-LANZAMIENTO — Lean (3 meses, ancla)
C34: Meta Ads pre-Day-D | E34: 3 | F34: 400 | G34: =E34*F34 -> 1200 | H34: =IF(G34=0,"",G34/G109) -> 0.010715434
C35: Material POP / señalética | E35: 1 | F35: 600 | G35: =E35*F35 -> 600 | H35: =IF(G35=0,"",G35/G109) -> 0.0053577169
C36: Demos B2B adicionales | E36: 1 | F36: 450 | G36: =E36*F36 -> 450 | H36: =IF(G36=0,"",G36/G109) -> 0.0040182877
C37: Subtotal marketing pre-lanzamiento Lean | G37: =SUM(G34:G36) -> 2250 | H37: =IF(G37=0,"",G37/G109) -> 0.020091438
C39: MANO DE OBRA FASE 0 (3 meses — incluida en Fase 0, no duplicar en one-shots)
C40: 4× Sales bootstrap (350 c/u) — sueldos bajo AVGH; validar contratos [PENDIENTE]. Tarifas mensuales × 3 meses pre-Day-D. Comisiones Sales: $40/firma (estimado en ESTA, no duplicado aquí).
C42: Founder CEO/CTO (1000/mes) | E42: 3 | F42: 1000 | G42: =E42*F42 -> 3000 | H42: =IF(G42=0,"",G42/G109) -> 0.026788584
C43: Co-CEO Head Sales&Ops (1000/mes) | E43: 3 | F43: 1000 | G43: =E43*F43 -> 3000 | H43: =IF(G43=0,"",G43/G109) -> 0.026788584
C44: Dev junior (Flutter/Laravel) (600/mes) | E44: 3 | F44: 600 | G44: =E44*F44 -> 1800 | H44: =IF(G44=0,"",G44/G109) -> 0.016073151
C45: 4× Sales B2B (350/mes c/u base) | E45: 3 | F45: 1400 | G45: =E45*F45 -> 4200 | H45: =IF(G45=0,"",G45/G109) -> 0.037504018
C46: CS + Community Manager (400/mes) | E46: 3 | F46: 400 | G46: =E46*F46 -> 1200 | H46: =IF(G46=0,"",G46/G109) -> 0.010715434
C47: Herramientas IA (425/mes) | E47: 3 | F47: 425 | G47: =E47*F47 -> 1275 | H47: =IF(G47=0,"",G47/G109) -> 0.011385148
C48: Contador + Abogado (330/mes) | E48: 3 | F48: 330 | G48: =E48*F48 -> 990 | H48: =IF(G48=0,"",G48/G109) -> 0.0088402329
C49: Subtotal mano de obra Fase 0 (3 meses) | G49: =SUM(G42:G48) -> 15465 | H49: =IF(G49=0,"",G49/G109) -> 0.13809515
C51: TRANSPORTE Y MOVILIDAD B2B (referencia desglose)
...

Sheet Hoja3
E7: Zonix Pharma — Resumen inversión (v3.9.1)
E9: A — Use of funds (TOTAL SAFE Lean) | K9: TIMELINE + RESUMEN FASE 0 (v3.9.1)
E10: Bloque | G10: USD | H10: % del total | K10: One-shots (legal+intro+HQ) | M10: ='Detallado de la inversión.'!G76 -> 14208
E11: One-shots (legal + intro + HQ) | G11: ='Detallado de la inversión.'!G76 -> 14208 | H11: =G11/G15 -> 0.12687074 | K11: Fase 0 operativa (sin one-shots) | M11: ='Detallado de la inversión.'!G78 -> 17377
E12: Burn 12 meses (M1–M12) | G12: ='Detallado de la inversión.'!G107 -> 97290 | H12: =G12/G15 -> 0.8687538 | K12: Fase 0 total (T+0→Day-D) | M12: ='Detallado de la inversión.'!G72 -> 33835
E13: Reserva caja Lean | G13: ='Detallado de la inversión.'!G108 -> 490 | H13: =G13/G15 -> 0.0043754688 | K13: Sub-fase 0a (T+0→T+30) | M13: ='Detallado de la inversión.'!G69 -> 17813
K14: Sub-fase 0b (T+30→T+60) | M14: ='Detallado de la inversión.'!G70 -> 8011
E15: TOTAL SAFE Lean | G15: ='Detallado de la inversión.'!G109 -> 111988 | H15: =SUM(H11:H13) -> 1 | K15: Sub-fase 0c (T+60→T+90) | M15: ='Detallado de la inversión.'!G71 -> 8011
E16: Marketing pre-lanzamiento (~2.250 USD) incluido en Fase 0 — ver Sección B. Unit economics → pestaña ESTA SI VALE. | K16: Caja al Day-D (inicio M1) | M16: ='Detallado de la inversión.'!G74 -> 78153
K17: Burn 12 meses (M1–M12) | M17: ='Detallado de la inversión.'!G107 -> 97290
E18: B — Desglose operativo Fase 0 (enlace Detallado) | K18: Reserva caja | M18: ='Detallado de la inversión.'!G108 -> 490
E19: Informativo — no sumar bloques al TOTAL SAFE (Sección A). Subtotal Fase 0 = modelo timing 0a–0c, no suma de columnas visibles. | K19: TOTAL capital SAFE | M19: ='Detallado de la inversión.'!G109 -> 111988
E20: Descripción | G20: Cant. | H20: USD/u | I20: Total USD | K20: SAFE cap ref. → ~18.66% equity | M20: =M19/600000 -> 0.18664667
E21: Constitución empresa (sin BPF/CPE farmacia)
E22: ='Detallado de la inversión.'!C11 -> Registro Mercantil + acta constitutiva | G22: ='Detallado de la inversión.'!E11 -> 1 | H22: ='Detallado de la inversión.'!F11 -> 1200 | I22: ='Detallado de la inversión.'!G11 -> 1200 | K22: Ref. mensual post-Day-D
E23: ='Detallado de la inversión.'!C12 -> SENIAT — inscripción / trámites RIF | G23: ='Detallado de la inversión.'!E12 -> 1 | H23: ='Detallado de la inversión.'!F12 -> 600 | I23: ='Detallado de la inversión.'!G12 -> 600 | K23: MO operativa (subtotal) | M23: ='Detallado de la inversión.'!G90 -> 5155
E24: ='Detallado de la inversión.'!C13 -> Licencia / permisos municipales HQ | G24: ='Detallado de la inversión.'!E13 -> 1 | H24: ='Detallado de la inversión.'!F13 -> 1500 | I24: ='Detallado de la inversión.'!G13 -> 1500 | K24: Marketing mensual (subtotal) | M24: ='Detallado de la inversión.'!G103 -> 2953
E25: ='Detallado de la inversión.'!C14 -> Permiso bomberos (local operativo) | G25: ='Detallado de la inversión.'!E14 -> 1 | H25: ='Detallado de la inversión.'!F14 -> 1100 | I25: ='Detallado de la inversión.'!G14 -> 1100 | K25: Incluido en burn M1–M12. No sumar a one-shots ni duplicar MO Fase 0. Unit economics → pestaña ESTA SI VALE.
E26: ='Detallado de la inversión.'!C15 -> Apertura cuenta bancaria empresa | G26: ='Detallado de la inversión.'!E15 -> 1 | H26: ='Detallado de la inversión.'!F15 -> 100 | I26: ='Detallado de la inversión.'!G15 -> 100
E27: ='Detallado de la inversión.'!C16 -> Sello digital + factura digital SENIAT | G27: ='Detallado de la inversión.'!E16 -> 1 | H27: ='Detallado de la inversión.'!F16 -> 200 | I27: ='Detallado de la inversión.'!G16 -> 200
E28: ='Detallado de la inversión.'!C17 -> Registro marca SAPI (paralelo) | G28: ='Detallado de la inversión.'!E17 -> 1 | H28: ='Detallado de la inversión.'!F17 -> 350 | I28: ='Detallado de la inversión.'!G17 -> 350
E29: ='Detallado de la inversión.'!C18 -> Subtotal constitución empresa | I29: ='Detallado de la inversión.'!G18 -> 5050
E31: Introducción al mercado / demo
E32: ='Detallado de la inversión.'!C25 -> Website landing + dominio | G32: ='Detallado de la inversión.'!E25 -> 1 | H32: ='Detallado de la inversión.'!F25 -> 800 | I32: ='Detallado de la inversión.'!G25 -> 800
E33: ='Detallado de la inversión.'!C26 -> Brochures y material impreso B2B | G33: ='Detallado de la inversión.'!E26 -> 1 | H33: ='Detallado de la inversión.'!F26 -> 400 | I33: ='Detallado de la inversión.'!G26 -> 400
E34: ='Detallado de la inversión.'!C27 -> Tablets demo farmacia | G34: ='Detallado de la inversión.'!E27 -> 2 | H34: ='Detallado de la inversión.'!F27 -> 350 | I34: ='Detallado de la inversión.'!G27 -> 700
E35: ='Detallado de la inversión.'!C28 -> Visitas comerciales pre-Day-D | G35: ='Detallado de la inversión.'!E28 -> 1 | H35: ='Detallado de la inversión.'!F28 -> 500 | I35: ='Detallado de la inversión.'!G28 -> 500
E36: ='Detallado de la inversión.'!C29 -> Reservas operativas primer mes | G36: ='Detallado de la inversión.'!E29 -> 1 | H36: ='Detallado de la inversión.'!F29 -> 608 | I36: ='Detallado de la inversión.'!G29 -> 608
E37: ='Detallado de la inversión.'!C30 -> Video pitch B2B farmacia (one-shot) | G37: ='Detallado de la inversión.'!E30 -> 1 | H37: ='Detallado de la inversión.'!F30 -> 800 | I37: ='Detallado de la inversión.'!G30 -> 800
E38: ='Detallado de la inversión.'!C31 -> Subtotal intro mercado Lean | I38: ='Detallado de la inversión.'!G31 -> 3808
E40: Marketing pre-lanzamiento (3 meses)
E41: ='Detallado de la inversión.'!C34 -> Meta Ads pre-Day-D | G41: ='Detallado de la inversión.'!E34 -> 3 | H41: ='Detallado de la inversión.'!F34 -> 400 | I41: ='Detallado de la inversión.'!G34 -> 1200
E42: ='Detallado de la inversión.'!C35 -> Material POP / señalética | G42: ='Detallado de la inversión.'!E35 -> 1 | H42: ='Detallado de la inversión.'!F35 -> 600 | I42: ='Detallado de la inversión.'!G35 -> 600
E43: ='Detallado de la inversión.'!C36 -> Demos B2B adicionales | G43: ='Detallado de la inversión.'!E36 -> 1 | H43: ='Detallado de la inversión.'!F36 -> 450 | I43: ='Detallado de la inversión.'!G36 -> 450
E44: ='Detallado de la inversión.'!C37 -> Subtotal marketing pre-lanzamiento Lean | I44: ='Detallado de la inversión.'!G37 -> 2250
E46: Mano de obra Fase 0 (3 meses)
E47: ='Detallado de la inversión.'!C42 -> Founder CEO/CTO (1000/mes) | G47: ='Detallado de la inversión.'!E42 -> 3 | H47: ='Detallado de la inversión.'!F42 -> 1000 | I47: ='Detallado de la inversión.'!G42 -> 3000
E48: ='Detallado de la inversión.'!C43 -> Co-CEO Head Sales&Ops (1000/mes) | G48: ='Detallado de la inversión.'!E43 -> 3 | H48: ='Detallado de la inversión.'!F43 -> 1000 | I48: ='Detallado de la inversión.'!G43 -> 3000
E49: ='Detallado de la inversión.'!C44 -> Dev junior (Flutter/Laravel) (600/mes) | G49: ='Detallado de la inversión.'!E44 -> 3 | H49: ='Detallado de la inversión.'!F44 -> 600 | I49: ='Detallado de la inversión.'!G44 -> 1800
E50: ='Detallado de la inversión.'!C45 -> 4× Sales B2B (350/mes c/u base) | G50: ='Detallado de la inversión.'!E45 -> 3 | H50: ='Detallado de la inversión.'!F45 -> 1400 | I50: ='Detallado de la inversión.'!G45 -> 4200
...

Sheet Hoja1
E1: Zonix Pharma — inversión Fase 0 (espejo Detallado v3.9.1) | L1: RESUMEN CAPEX (v3.9.1)
L2: Refs informativas — HQ ya en one-shots; no sumar CapEx + TOTAL SAFE.
E3: Datos ZonixPharma — enlaces a Detallado. One-shots en Hoja3 Sección A. No sumar bloques al TOTAL SAFE. Marketplace SaaS (sin rubros producción física). | L3: Inversión CapEx HQ | M3: ='Detallado de la inversión.'!G66 -> 5350
L4: % CapEx / TOTAL SAFE Lean | M4: =M3/'Detallado de la inversión.'!G109 -> 0.047772976
E5: Descripción | G5: Cant. | H5: USD/u | I5: Total USD | J5: % SAFE | L5: TOTAL SAFE Lean (ref.) | M5: ='Detallado de la inversión.'!G109 -> 111988
E6: equipos | L6: Burn mensual ref. (MO+mkt) | M6: ='Detallado de la inversión.'!G90+'Detallado de la inversión.'!G103 -> 8108
E7: ='Detallado de la inversión.'!C62 -> PC recepción / ventas | G7: ='Detallado de la inversión.'!E62 -> 1 | H7: ='Detallado de la inversión.'!F62 -> 800 | I7: ='Detallado de la inversión.'!G62 -> 800 | J7: ='Detallado de la inversión.'!H62 -> 0.0071436225 | L7: Reserva caja (ref.) | M7: ='Detallado de la inversión.'!G108 -> 490
E8: ='Detallado de la inversión.'!C63 -> PC administración | G8: ='Detallado de la inversión.'!E63 -> 1 | H8: ='Detallado de la inversión.'!F63 -> 850 | I8: ='Detallado de la inversión.'!G63 -> 850 | J8: ='Detallado de la inversión.'!H63 -> 0.0075900989 | L8: % equity SAFE (ref.) | M8: =M5/600000 -> 0.18664667
E9: ='Detallado de la inversión.'!C64 -> PC desarrollo | G9: ='Detallado de la inversión.'!E64 -> 1 | H9: ='Detallado de la inversión.'!F64 -> 950 | I9: ='Detallado de la inversión.'!G64 -> 950 | J9: ='Detallado de la inversión.'!H64 -> 0.0084830518
E10: ='Detallado de la inversión.'!C65 -> PC puesto flexible | G10: ='Detallado de la inversión.'!E65 -> 1 | H10: ='Detallado de la inversión.'!F65 -> 1100 | I10: ='Detallado de la inversión.'!G65 -> 1100 | J10: ='Detallado de la inversión.'!H65 -> 0.009822481 | L10: Use of funds → Hoja3 Sección A
E12: Subtotal equipos (4 PCs) | I12: =SUM('Detallado de la inversión.'!G62:G65) -> 3700
E14: adecuacion
E15: ='Detallado de la inversión.'!C60 -> Depósito + amueblado HQ casa | G15: ='Detallado de la inversión.'!E60 -> 1 | H15: ='Detallado de la inversión.'!F60 -> 1250 | I15: ='Detallado de la inversión.'!G60 -> 1250 | J15: ='Detallado de la inversión.'!H60 -> 0.01116191
E16: ='Detallado de la inversión.'!C61 -> Adecuación HQ (pintura, señalética) | G16: ='Detallado de la inversión.'!E61 -> 1 | H16: ='Detallado de la inversión.'!F61 -> 400 | I16: ='Detallado de la inversión.'!G61 -> 400 | J16: ='Detallado de la inversión.'!H61 -> 0.0035718113
E18: Subtotal adecuación HQ | I18: =SUM('Detallado de la inversión.'!G60:G61) -> 1650
E20: mano de obra
E21: ='Detallado de la inversión.'!C42 -> Founder CEO/CTO (1000/mes) | G21: ='Detallado de la inversión.'!E42 -> 3 | H21: ='Detallado de la inversión.'!F42 -> 1000 | I21: ='Detallado de la inversión.'!G42 -> 3000 | J21: ='Detallado de la inversión.'!H42 -> 0.026788584
E22: ='Detallado de la inversión.'!C43 -> Co-CEO Head Sales&Ops (1000/mes) | G22: ='Detallado de la inversión.'!E43 -> 3 | H22: ='Detallado de la inversión.'!F43 -> 1000 | I22: ='Detallado de la inversión.'!G43 -> 3000 | J22: ='Detallado de la inversión.'!H43 -> 0.026788584
E23: ='Detallado de la inversión.'!C44 -> Dev junior (Flutter/Laravel) (600/mes) | G23: ='Detallado de la inversión.'!E44 -> 3 | H23: ='Detallado de la inversión.'!F44 -> 600 | I23: ='Detallado de la inversión.'!G44 -> 1800 | J23: ='Detallado de la inversión.'!H44 -> 0.016073151
E24: ='Detallado de la inversión.'!C45 -> 4× Sales B2B (350/mes c/u base) | G24: ='Detallado de la inversión.'!E45 -> 3 | H24: ='Detallado de la inversión.'!F45 -> 1400 | I24: ='Detallado de la inversión.'!G45 -> 4200 | J24: ='Detallado de la inversión.'!H45 -> 0.037504018
E25: ='Detallado de la inversión.'!C46 -> CS + Community Manager (400/mes) | G25: ='Detallado de la inversión.'!E46 -> 3 | H25: ='Detallado de la inversión.'!F46 -> 400 | I25: ='Detallado de la inversión.'!G46 -> 1200 | J25: ='Detallado de la inversión.'!H46 -> 0.010715434
E26: ='Detallado de la inversión.'!C47 -> Herramientas IA (425/mes) | G26: ='Detallado de la inversión.'!E47 -> 3 | H26: ='Detallado de la inversión.'!F47 -> 425 | I26: ='Detallado de la inversión.'!G47 -> 1275 | J26: ='Detallado de la inversión.'!H47 -> 0.011385148
E27: ='Detallado de la inversión.'!C48 -> Contador + Abogado (330/mes) | G27: ='Detallado de la inversión.'!E48 -> 3 | H27: ='Detallado de la inversión.'!F48 -> 330 | I27: ='Detallado de la inversión.'!G48 -> 990 | J27: ='Detallado de la inversión.'!H48 -> 0.0088402329
E28: ='Detallado de la inversión.'!C49 -> Subtotal mano de obra Fase 0 (3 meses) | I28: ='Detallado de la inversión.'!G49 -> 15465 | J28: ='Detallado de la inversión.'!H49 -> 0.13809515
E30: transporte
E31: ='Detallado de la inversión.'!C54 -> Visitas comerciales Valencia (combustible / terceros) | G31: ='Detallado de la inversión.'!E54 -> 3 | H31: ='Detallado de la inversión.'!F54 -> 167 | I31: ='Detallado de la inversión.'!G54 -> 501 | J31: ='Detallado de la inversión.'!H54 -> 0.0044736936
E32: ='Detallado de la inversión.'!C55 -> Logística material demo (tablets, POP) | G32: ='Detallado de la inversión.'!E55 -> 1 | H32: ='Detallado de la inversión.'!F55 -> 200 | I32: ='Detallado de la inversión.'!G55 -> 200 | J32: ='Detallado de la inversión.'!H55 -> 0.0017859056
E33: ='Detallado de la inversión.'!C56 -> Gira medios / eventos farmacia (opcional Lean) | G33: ='Detallado de la inversión.'!E56 -> 1 | H33: ='Detallado de la inversión.'!F56 -> 350 | I33: ='Detallado de la inversión.'!G56 -> 350 | J33: ='Detallado de la inversión.'!H56 -> 0.0031253349
E34: ='Detallado de la inversión.'!C57 -> Subtotal transporte referencia Fase 0 | I34: ='Detallado de la inversión.'!G57 -> 1051 | J34: ='Detallado de la inversión.'!H57 -> 0.0093849341
E36: alquiler
E37: ='Detallado de la inversión.'!C95 -> HQ casa (arriendo + servicios) | G37: ='Detallado de la inversión.'!E95 -> 0 | H37: ='Detallado de la inversión.'!F95 -> 500 | I37: ='Detallado de la inversión.'!G95 -> 500 | J37: ='Detallado de la inversión.'!H95 -> 0.0044647641
E39: Depósito HQ (one-shot) incluido en bloque adecuación. Arriendo mensual post-Day-D — ref. burn Detallado.
E41: constitucion empresa y permisos
E42: ='Detallado de la inversión.'!C11 -> Registro Mercantil + acta constitutiva | G42: ='Detallado de la inversión.'!E11 -> 1 | H42: ='Detallado de la inversión.'!F11 -> 1200 | I42: ='Detallado de la inversión.'!G11 -> 1200 | J42: ='Detallado de la inversión.'!H11 -> 0.010715434
E43: ='Detallado de la inversión.'!C12 -> SENIAT — inscripción / trámites RIF | G43: ='Detallado de la inversión.'!E12 -> 1 | H43: ='Detallado de la inversión.'!F12 -> 600 | I43: ='Detallado de la inversión.'!G12 -> 600 | J43: ='Detallado de la inversión.'!H12 -> 0.0053577169
E44: ='Detallado de la inversión.'!C13 -> Licencia / permisos municipales HQ | G44: ='Detallado de la inversión.'!E13 -> 1 | H44: ='Detallado de la inversión.'!F13 -> 1500 | I44: ='Detallado de la inversión.'!G13 -> 1500 | J44: ='Detallado de la inversión.'!H13 -> 0.013394292
E45: ='Detallado de la inversión.'!C14 -> Permiso bomberos (local operativo) | G45: ='Detallado de la inversión.'!E14 -> 1 | H45: ='Detallado de la inversión.'!F14 -> 1100 | I45: ='Detallado de la inversión.'!G14 -> 1100 | J45: ='Detallado de la inversión.'!H14 -> 0.009822481
E46: ='Detallado de la inversión.'!C15 -> Apertura cuenta bancaria empresa | G46: ='Detallado de la inversión.'!E15 -> 1 | H46: ='Detallado de la inversión.'!F15 -> 100 | I46: ='Detallado de la inversión.'!G15 -> 100 | J46: ='Detallado de la inversión.'!H15 -> 0.00089295282
E47: ='Detallado de la inversión.'!C16 -> Sello digital + factura digital SENIAT | G47: ='Detallado de la inversión.'!E16 -> 1 | H47: ='Detallado de la inversión.'!F16 -> 200 | I47: ='Detallado de la inversión.'!G16 -> 200 | J47: ='Detallado de la inversión.'!H16 -> 0.0017859056
E48: ='Detallado de la inversión.'!C17 -> Registro marca SAPI (paralelo) | G48: ='Detallado de la inversión.'!E17 -> 1 | H48: ='Detallado de la inversión.'!F17 -> 350 | I48: ='Detallado de la inversión.'!G17 -> 350 | J48: ='Detallado de la inversión.'!H17 -> 0.0031253349
...

Sheet Hoja2
C1: mensual
B2: Meta Ads M1-6 (USD) | C2: 800
B3: Meta Ads M7-12 (USD) | C3: 500
B4: Valla pequeña desde M3 (USD) | C4: 350

Sheet ESTA SI VALE
E3: Datos ZonixPharma — espejo Detallado/Hoja1. Bloques ESTA = vista due diligence. TOTAL SAFE oficial → Hoja3 §A. No sumar bloques al SAFE.
E7: Zonix Pharma — ESTA SI VALE (espejo Pizza v3.9.1) | M7: Zonix Pharma — Unit economics y escenarios
P8: gastos fijos mensuales (ref. burn/activas — no sumar SAFE)
E9: Descripción | G9: Cant. | H9: USD/u | I9: Total USD | J9: % SAFE | K9: Año 2 ref. | M9: Concepto | O9: Valor | S9: Fuente
E10: Factor Año 2 MO (+40%) | K10: 0.4 | M10: ARPF placeholder (USD/mes) | O10: 50 | S10: UNIT_ECONOMICS
E11: Mano de obra (Fase 0 — 3 meses) | M11: CAC farmacia (USD) | O11: 139 | S11: UNIT_ECONOMICS
E12: ='Detallado de la inversión.'!C42 -> Founder CEO/CTO (1000/mes) | G12: ='Detallado de la inversión.'!E42 -> 3 | H12: ='Detallado de la inversión.'!F42 -> 1000 | I12: ='Detallado de la inversión.'!G42 -> 3000 | J12: ='Detallado de la inversión.'!H42 -> 0.026788584 | K12: =I12*(1+$K$10) -> 4200 | M12: Churn mensual target | O12: 0.05 | P12: Escenario margen 50%-30% | S12: UNIT_ECONOMICS
E13: ='Detallado de la inversión.'!C43 -> Co-CEO Head Sales&Ops (1000/mes) | G13: ='Detallado de la inversión.'!E43 -> 3 | H13: ='Detallado de la inversión.'!F43 -> 1000 | I13: ='Detallado de la inversión.'!G43 -> 3000 | J13: ='Detallado de la inversión.'!H43 -> 0.026788584 | K13: =I13*(1+$K$10) -> 4200 | M13: LTV (USD) | O13: 1000 | P13: Mes 1 | Q13: =IF('Año 1'!D19=0,0,='ESTA SI VALE'!$I$73/'Año 1'!D19) -> #VALUE! | S13: UNIT_ECONOMICS
E14: ='Detallado de la inversión.'!C44 -> Dev junior (Flutter/Laravel) (600/mes) | G14: ='Detallado de la inversión.'!E44 -> 3 | H14: ='Detallado de la inversión.'!F44 -> 600 | I14: ='Detallado de la inversión.'!G44 -> 1800 | J14: ='Detallado de la inversión.'!H44 -> 0.016073151 | K14: =I14*(1+$K$10) -> 2520 | M14: LTV / CAC | O14: 7.2 | P14: Mes 2 | Q14: =H55 -> 0 | S14: UNIT_ECONOMICS
E15: ='Detallado de la inversión.'!C45 -> 4× Sales B2B (350/mes c/u base) | G15: ='Detallado de la inversión.'!E45 -> 3 | H15: ='Detallado de la inversión.'!F45 -> 1400 | I15: ='Detallado de la inversión.'!G45 -> 4200 | J15: ='Detallado de la inversión.'!H45 -> 0.037504018 | K15: =I15*(1+$K$10) -> 5880 | M15: Payback CAC (meses) | O15: 2.8 | P15: Mes 3 | Q15: =H55 -> 0 | S15: UNIT_ECONOMICS
E16: ='Detallado de la inversión.'!C46 -> CS + Community Manager (400/mes) | G16: ='Detallado de la inversión.'!E46 -> 3 | H16: ='Detallado de la inversión.'!F46 -> 400 | I16: ='Detallado de la inversión.'!G46 -> 1200 | J16: ='Detallado de la inversión.'!H46 -> 0.010715434 | K16: =I16*(1+$K$10) -> 1680 | M16: Margen bruto plataforma | O16: 0.92 | P16: TOTAL ref. | Q16: =SUM(Q13:Q15) -> #VALUE! | S16: UNIT_ECONOMICS
E17: ='Detallado de la inversión.'!C47 -> Herramientas IA (425/mes) | G17: ='Detallado de la inversión.'!E47 -> 3 | H17: ='Detallado de la inversión.'!F47 -> 425 | I17: ='Detallado de la inversión.'!G47 -> 1275 | J17: ='Detallado de la inversión.'!H47 -> 0.011385148 | K17: =I17*(1+$K$10) -> 1785 | M17: Cuota Basic (USD/mes) | O17: 25 | P17: Escenario margen 60%-40% | S17: PROPUESTA B2B §5
E18: ='Detallado de la inversión.'!C48 -> Contador + Abogado (330/mes) | G18: ='Detallado de la inversión.'!E48 -> 3 | H18: ='Detallado de la inversión.'!F48 -> 330 | I18: ='Detallado de la inversión.'!G48 -> 990 | J18: ='Detallado de la inversión.'!H48 -> 0.0088402329 | K18: =I18*(1+$K$10) -> 1386 | M18: Cuota Pro (USD/mes) | O18: 40 | P18: Mes 1 | Q18: =IF('Año 1'!D19=0,0,='ESTA SI VALE'!$I$73/'Año 1'!D19) -> #VALUE! | S18: PROPUESTA B2B §5
E19: ='Detallado de la inversión.'!C49 -> Subtotal mano de obra Fase 0 (3 meses) | I19: ='Detallado de la inversión.'!G49 -> 15465 | J19: ='Detallado de la inversión.'!H49 -> 0.13809515 | K19: =SUM(K12:K18) -> 21651 | M19: Cuota Enterprise (USD/mes) | O19: 55 | P19: Mes 2 | Q19: =H55 -> 0 | S19: PROPUESTA B2B §5
M20: Mix Basic / Pro / Enterprise | O20: 60/30/10 | P20: Mes 3 | Q20: =H55 -> 0 | S20: PROYECCION §1.2
E21: Factor Año 2 transporte (+30%) | K21: 0.3 | M21: Farmacias activas equilibrio Lean (M12 v3.3) | O21: 159 | P21: TOTAL ref. | Q21: =SUM(Q18:Q20) -> #VALUE! | S21: PROYECCION — 4× Sales
E22: Transporte local (B2B / demo) | P22: Escenario margen 70%-50%
E23: ='Detallado de la inversión.'!C54 -> Visitas comerciales Valencia (combustible / terceros) | G23: ='Detallado de la inversión.'!E54 -> 3 | H23: ='Detallado de la inversión.'!F54 -> 167 | I23: ='Detallado de la inversión.'!G54 -> 501 | J23: ='Detallado de la inversión.'!H54 -> 0.0044736936 | K23: =I23*(1+$K$21) -> 651.3 | M23: ESCENARIOS CAPITAL (tiers) | P23: Mes 1 | Q23: =IF('Año 1'!D19=0,0,='ESTA SI VALE'!$I$73/'Año 1'!D19) -> #VALUE!
E24: ='Detallado de la inversión.'!C55 -> Logística material demo (tablets, POP) | G24: ='Detallado de la inversión.'!E55 -> 1 | H24: ='Detallado de la inversión.'!F55 -> 200 | I24: ='Detallado de la inversión.'!G55 -> 200 | J24: ='Detallado de la inversión.'!H55 -> 0.0017859056 | K24: =I24*(1+$K$21) -> 260 | M24: Tier | O24: Capital | P24: Mes 2 | Q24: =H55 -> 0 | S24: SAFE cap
E25: ='Detallado de la inversión.'!C56 -> Gira medios / eventos farmacia (opcional Lean) | G25: ='Detallado de la inversión.'!E56 -> 1 | H25: ='Detallado de la inversión.'!F56 -> 350 | I25: ='Detallado de la inversión.'!G56 -> 350 | J25: ='Detallado de la inversión.'!H56 -> 0.0031253349 | K25: =I25*(1+$K$21) -> 455 | M25: Lean — bootstrap 4× Sales (Carabobo) — capital (USD) | O25: 111988 | P25: Mes 3 | Q25: =H55 -> 0 | S25: 600000
E26: ='Detallado de la inversión.'!C57 -> Subtotal transporte referencia Fase 0 | I26: ='Detallado de la inversión.'!G57 -> 1051 | J26: ='Detallado de la inversión.'!H57 -> 0.0093849341 | K26: =SUM(K23:K25) -> 1366.3 | M26: Lean+ — 4× Sales curva ×1,15 (mismo capital Lean) — capital (USD) | O26: 111988 | P26: TOTAL ref. | Q26: =SUM(Q23:Q25) -> #VALUE! | S26: 600000
M27: Base — piso de mercado — capital (USD) | O27: 157268 | P27: 10898 | Q27: 159 | S27: 912814
E28: Constitución one-shot (sin escalación Año 2) | K28: 0 | M28: Growth — mercado pleno — capital (USD) | O28: 187478 | P28: 12698 | Q28: 159 | S28: 1205345
E29: Constitución empresa y permisos (C.A. — sin BPF/CPE piloto) | M29: Blitz — Carabobo 6× Sales — capital (USD) | O29: 184878 | P29: 11998 | Q29: 238 | S29: 1287681
E30: ='Detallado de la inversión.'!C11 -> Registro Mercantil + acta constitutiva | G30: ='Detallado de la inversión.'!E11 -> 1 | H30: ='Detallado de la inversión.'!F11 -> 1200 | I30: ='Detallado de la inversión.'!G11 -> 1200 | J30: ='Detallado de la inversión.'!H11 -> 0.010715434 | K30: =I30*(1+$K$28) -> 1200
E31: ='Detallado de la inversión.'!C12 -> SENIAT — inscripción / trámites RIF | G31: ='Detallado de la inversión.'!E12 -> 1 | H31: ='Detallado de la inversión.'!F12 -> 600 | I31: ='Detallado de la inversión.'!G12 -> 600 | J31: ='Detallado de la inversión.'!H12 -> 0.0053577169 | K31: =I31*(1+$K$28) -> 600 | M31: ESCENARIOS PROYECCION §7 (P10/P50/P90)
E32: ='Detallado de la inversión.'!C13 -> Licencia / permisos municipales HQ | G32: ='Detallado de la inversión.'!E13 -> 1 | H32: ='Detallado de la inversión.'!F13 -> 1500 | I32: ='Detallado de la inversión.'!G13 -> 1500 | J32: ='Detallado de la inversión.'!H13 -> 0.013394292 | K32: =I32*(1+$K$28) -> 1500 | M32: Escenario | O32: Activas M12 | P32: ARPF | Q32: Cash M12
E33: ='Detallado de la inversión.'!C14 -> Permiso bomberos (local operativo) | G33: ='Detallado de la inversión.'!E14 -> 1 | H33: ='Detallado de la inversión.'!F14 -> 1100 | I33: ='Detallado de la inversión.'!G14 -> 1100 | J33: ='Detallado de la inversión.'!H14 -> 0.009822481 | K33: =I33*(1+$K$28) -> 1100 | M33: P10 pesimista | O33: 120 | P33: 40 | Q33: 25000
E34: ='Detallado de la inversión.'!C15 -> Apertura cuenta bancaria empresa | G34: ='Detallado de la inversión.'!E15 -> 1 | H34: ='Detallado de la inversión.'!F15 -> 100 | I34: ='Detallado de la inversión.'!G15 -> 100 | J34: ='Detallado de la inversión.'!H15 -> 0.00089295282 | K34: =I34*(1+$K$28) -> 100 | M34: P50 base | O34: 159 | P34: 50 | Q34: 40831
E35: ='Detallado de la inversión.'!C16 -> Sello digital + factura digital SENIAT | G35: ='Detallado de la inversión.'!E16 -> 1 | H35: ='Detallado de la inversión.'!F16 -> 200 | I35: ='Detallado de la inversión.'!G16 -> 200 | J35: ='Detallado de la inversión.'!H16 -> 0.0017859056 | K35: =I35*(1+$K$28) -> 200 | M35: P90 optimista | O35: 200 | P35: 55 | Q35: 52000
E36: ='Detallado de la inversión.'!C17 -> Registro marca SAPI (paralelo) | G36: ='Detallado de la inversión.'!E17 -> 1 | H36: ='Detallado de la inversión.'!F17 -> 350 | I36: ='Detallado de la inversión.'!G17 -> 350 | J36: ='Detallado de la inversión.'!H17 -> 0.0031253349 | K36: =I36*(1+$K$28) -> 350 | M36: Lean+ stretch (4×, curva ×1,15) | O36: 183 | P36: 50 | Q36: 49825
E37: ='Detallado de la inversión.'!C18 -> Subtotal constitución empresa | I37: ='Detallado de la inversión.'!G18 -> 5050 | J37: ='Detallado de la inversión.'!H18 -> 0.045094117 | K37: =SUM(K30:K36) -> 5050 | M37: Blitz stretch (6× Sales) | O37: 238 | P37: 50 | Q37: 87020
E39: Factor Año 2 intro/marketing (-50% one-shot) | K39: -0.5
E40: Introducción al mercado; primeros 3 meses
E41: ='Detallado de la inversión.'!C25 -> Website landing + dominio | G41: ='Detallado de la inversión.'!E25 -> 1 | H41: ='Detallado de la inversión.'!F25 -> 800 | I41: ='Detallado de la inversión.'!G25 -> 800 | J41: ='Detallado de la inversión.'!H25 -> 0.0071436225 | K41: =I41*(1+$K$39) -> 400
E42: ='Detallado de la inversión.'!C26 -> Brochures y material impreso B2B | G42: ='Detallado de la inversión.'!E26 -> 1 | H42: ='Detallado de la inversión.'!F26 -> 400 | I42: ='Detallado de la inversión.'!G26 -> 400 | J42: ='Detallado de la inversión.'!H26 -> 0.0035718113 | K42: =I42*(1+$K$39) -> 200
E43: ='Detallado de la inversión.'!C27 -> Tablets demo farmacia | G43: ='Detallado de la inversión.'!E27 -> 2 | H43: ='Detallado de la inversión.'!F27 -> 350 | I43: ='Detallado de la inversión.'!G27 -> 700 | J43: ='Detallado de la inversión.'!H27 -> 0.0062506697 | K43: =I43*(1+$K$39) -> 350
E44: ='Detallado de la inversión.'!C28 -> Visitas comerciales pre-Day-D | G44: ='Detallado de la inversión.'!E28 -> 1 | H44: ='Detallado de la inversión.'!F28 -> 500 | I44: ='Detallado de la inversión.'!G28 -> 500 | J44: ='Detallado de la inversión.'!H28 -> 0.0044647641 | K44: =I44*(1+$K$39) -> 250
E45: ='Detallado de la inversión.'!C29 -> Reservas operativas primer mes | G45: ='Detallado de la inversión.'!E29 -> 1 | H45: ='Detallado de la inversión.'!F29 -> 608 | I45: ='Detallado de la inversión.'!G29 -> 608 | J45: ='Detallado de la inversión.'!H29 -> 0.0054291531 | K45: =I45*(1+$K$39) -> 304
E46: ='Detallado de la inversión.'!C30 -> Video pitch B2B farmacia (one-shot) | G46: ='Detallado de la inversión.'!E30 -> 1 | H46: ='Detallado de la inversión.'!F30 -> 800 | I46: ='Detallado de la inversión.'!G30 -> 800 | J46: ='Detallado de la inversión.'!H30 -> 0.0071436225 | K46: =I46*(1+$K$39) -> 400
...

Sheet Año 1
B2: ITEMS | C2: DATOS
B3: ARPF placeholder USD/mes | C3: 50
B4: Cuota Basic USD/mes | C4: 25
B5: Cuota Pro USD/mes | C5: 40
B6: Cuota Enterprise USD/mes | C6: 55
B7: Mix Basic (ponderador) | C7: 0.6
B8: Mix Pro (ponderador) | C8: 0.3
B9: Mix Enterprise (ponderador) | C9: 0.1
B10: Churn mensual target | C10: 0.05
B11: Participación Inversor SAFE | C11: 0.1866
B12: Participación Founders | C12: =1-C11 -> 0.8134
B13: Tasa descuento VAN | C13: 0.25
B14: Capital SAFE Lean (USD) | C14: 111988
B15: Nota escenario | C15: Lean ancla pack
B16: AÑO 1 | C16: AÑO 1
C17: Mes 1 | D17: Mes 2 | E17: Mes 3 | F17: Mes 4 | G17: Mes 5 | H17: Mes 6 | I17: Mes 7 | J17: Mes 8 | K17: Mes 9 | L17: Mes 10 | M17: Mes 11 | N17: Mes 12 | O17: TOTAL
B18: Farmacias firmadas (altas mes) | C18: 13 | D18: 13 | E18: 14 | F18: 15 | G18: 15 | H18: 16 | I18: 16 | J18: 16 | K18: 17 | L18: 17 | M18: 17 | N18: 16 | O18: =SUM(C18:N18) -> 185
B19: Farmacias activas (stock cierre mes) | C19: 40 | D19: 51 | E19: 62 | F19: 74 | G19: 85 | H19: 97 | I19: 108 | J19: 119 | K19: 130 | L19: 141 | M19: 151 | N19: 159 | O19: =N19 -> 159
B21: Ingresos ($)
B22: Ingresos cuota fija B2B | C22: =C19*($C$7*$C$4+$C$8*$C$5+$C$9*$C$6) -> 1300 | D22: =D19*($C$7*$C$4+$C$8*$C$5+$C$9*$C$6) -> 1657.5 | E22: =E19*($C$7*$C$4+$C$8*$C$5+$C$9*$C$6) -> 2015 | F22: =F19*($C$7*$C$4+$C$8*$C$5+$C$9*$C$6) -> 2405 | G22: =G19*($C$7*$C$4+$C$8*$C$5+$C$9*$C$6) -> 2762.5 | H22: =H19*($C$7*$C$4+$C$8*$C$5+$C$9*$C$6) -> 3152.5 | I22: =I19*($C$7*$C$4+$C$8*$C$5+$C$9*$C$6) -> 3510 | J22: =J19*($C$7*$C$4+$C$8*$C$5+$C$9*$C$6) -> 3867.5 | ... N22: =N19*($C$7*$C$4+$C$8*$C$5+$C$9*$C$6) -> 5167.5 | O22: =SUM(C22:N22) -> 39552.5
B23: Ingresos comisión % GMV [EDITAR] | C23: =C19*($C$3-C22/C19) -> 700 | D23: =D19*($C$3-D22/D19) -> 892.5 | E23: =E19*($C$3-E22/E19) -> 1085 | F23: =F19*($C$3-F22/F19) -> 1295 | G23: =G19*($C$3-G22/G19) -> 1487.5 | H23: =H19*($C$3-H22/H19) -> 1697.5 | I23: =I19*($C$3-I22/I19) -> 1890 | J23: =J19*($C$3-J22/J19) -> 2082.5 | ... N23: =N19*($C$3-N22/N19) -> 2782.5 | O23: =SUM(C23:N23) -> 21297.5
B24: Ajuste billing pack PROYECCION §1.1 | C24: =1500-(C22+C23) -> -500 | D24: =2168-(D22+D23) -> -382 | E24: =3100-(E22+E23) -> 0 | F24: =3700-(F22+F23) -> 0 | G24: =4250-(G22+G23) -> 0 | H24: =4850-(H22+H23) -> 0 | I24: =5400-(I22+I23) -> 0 | J24: =5950-(J22+J23) -> 0 | K24: =6500-(K22+K23) -> 0 | L24: =7050-(L22+L23) -> 0 | M24: =7550-(M22+M23) -> 0 | N24: =7950-(N22+N23) -> 0 | O24: =SUM(C24:N24) -> -882
B25: Total Ingresos | C25: =C22+C23+C24 -> 1500 | D25: =D22+D23+D24 -> 2168 | E25: =E22+E23+E24 -> 3100 | F25: =F22+F23+F24 -> 3700 | G25: =G22+G23+G24 -> 4250 | H25: =H22+H23+H24 -> 4850 | I25: =I22+I23+I24 -> 5400 | J25: =J22+J23+J24 -> 5950 | ... N25: =N22+N23+N24 -> 7950 | O25: =SUM(C25:N25) -> 59968
B27: Costos ($)
B28: Dev junior (Flutter/Laravel) | C28: ='ESTA SI VALE'!$I$60 -> 600 | D28: ='ESTA SI VALE'!$I$60 -> 600 | E28: ='ESTA SI VALE'!$I$60 -> 600 | F28: ='ESTA SI VALE'!$I$60 -> 600 | G28: ='ESTA SI VALE'!$I$60 -> 600 | H28: ='ESTA SI VALE'!$I$60 -> 600 | I28: ='ESTA SI VALE'!$I$60 -> 600 | J28: ='ESTA SI VALE'!$I$60 -> 600 | ... N28: ='ESTA SI VALE'!$I$60 -> 600
B29: 4× Sales B2B | C29: ='ESTA SI VALE'!$I$61 -> 1400 | D29: ='ESTA SI VALE'!$I$61 -> 1400 | E29: ='ESTA SI VALE'!$I$61 -> 1400 | F29: ='ESTA SI VALE'!$I$61 -> 1400 | G29: ='ESTA SI VALE'!$I$61 -> 1400 | H29: ='ESTA SI VALE'!$I$61 -> 1400 | I29: ='ESTA SI VALE'!$I$61 -> 1400 | J29: ='ESTA SI VALE'!$I$61 -> 1400 | ... N29: ='ESTA SI VALE'!$I$61 -> 1400
B30: CS + Community Manager | C30: ='ESTA SI VALE'!$I$62 -> 400 | D30: ='ESTA SI VALE'!$I$62 -> 400 | E30: ='ESTA SI VALE'!$I$62 -> 400 | F30: ='ESTA SI VALE'!$I$62 -> 400 | G30: ='ESTA SI VALE'!$I$62 -> 400 | H30: ='ESTA SI VALE'!$I$62 -> 400 | I30: ='ESTA SI VALE'!$I$62 -> 400 | J30: ='ESTA SI VALE'!$I$62 -> 400 | ... N30: ='ESTA SI VALE'!$I$62 -> 400
B31: Founder + Co-CEO | C31: ='ESTA SI VALE'!$I$63 -> 2000 | D31: ='ESTA SI VALE'!$I$63 -> 2000 | E31: ='ESTA SI VALE'!$I$63 -> 2000 | F31: ='ESTA SI VALE'!$I$63 -> 2000 | G31: ='ESTA SI VALE'!$I$63 -> 2000 | H31: ='ESTA SI VALE'!$I$63 -> 2000 | I31: ='ESTA SI VALE'!$I$63 -> 2000 | J31: ='ESTA SI VALE'!$I$63 -> 2000 | ... N31: ='ESTA SI VALE'!$I$63 -> 2000
B32: Herramientas IA | C32: ='ESTA SI VALE'!$I$64 -> 425 | D32: ='ESTA SI VALE'!$I$64 -> 425 | E32: ='ESTA SI VALE'!$I$64 -> 425 | F32: ='ESTA SI VALE'!$I$64 -> 425 | G32: ='ESTA SI VALE'!$I$64 -> 425 | H32: ='ESTA SI VALE'!$I$64 -> 425 | I32: ='ESTA SI VALE'!$I$64 -> 425 | J32: ='ESTA SI VALE'!$I$64 -> 425 | ... N32: ='ESTA SI VALE'!$I$64 -> 425
B33: Contador + Abogado | C33: ='ESTA SI VALE'!$I$65 -> 330 | D33: ='ESTA SI VALE'!$I$65 -> 330 | E33: ='ESTA SI VALE'!$I$65 -> 330 | F33: ='ESTA SI VALE'!$I$65 -> 330 | G33: ='ESTA SI VALE'!$I$65 -> 330 | H33: ='ESTA SI VALE'!$I$65 -> 330 | I33: ='ESTA SI VALE'!$I$65 -> 330 | J33: ='ESTA SI VALE'!$I$65 -> 330 | ... N33: ='ESTA SI VALE'!$I$65 -> 330
B34: HQ casa (arriendo + servicios) | C34: ='ESTA SI VALE'!$I$66 -> 500 | D34: ='ESTA SI VALE'!$I$66 -> 500 | E34: ='ESTA SI VALE'!$I$66 -> 500 | F34: ='ESTA SI VALE'!$I$66 -> 500 | G34: ='ESTA SI VALE'!$I$66 -> 500 | H34: ='ESTA SI VALE'!$I$66 -> 500 | I34: ='ESTA SI VALE'!$I$66 -> 500 | J34: ='ESTA SI VALE'!$I$66 -> 500 | ... N34: ='ESTA SI VALE'!$I$66 -> 500
B35: Servicios oficina (electricidad, agua, internet) | C35: ='ESTA SI VALE'!$I$67 -> 80 | D35: ='ESTA SI VALE'!$I$67 -> 80 | E35: ='ESTA SI VALE'!$I$67 -> 80 | F35: ='ESTA SI VALE'!$I$67 -> 80 | G35: ='ESTA SI VALE'!$I$67 -> 80 | H35: ='ESTA SI VALE'!$I$67 -> 80 | I35: ='ESTA SI VALE'!$I$67 -> 80 | J35: ='ESTA SI VALE'!$I$67 -> 80 | ... N35: ='ESTA SI VALE'!$I$67 -> 80
B36: Hosting + SaaS + Firebase OTP | C36: ='ESTA SI VALE'!$I$68 -> 154 | D36: ='ESTA SI VALE'!$I$68 -> 154 | E36: ='ESTA SI VALE'!$I$68 -> 154 | F36: ='ESTA SI VALE'!$I$68 -> 154 | G36: ='ESTA SI VALE'!$I$68 -> 154 | H36: ='ESTA SI VALE'!$I$68 -> 154 | I36: ='ESTA SI VALE'!$I$68 -> 154 | J36: ='ESTA SI VALE'!$I$68 -> 154 | ... N36: ='ESTA SI VALE'!$I$68 -> 154
B37: Meta Ads | C37: 800 | D37: 800 | E37: 800 | F37: 800 | G37: 800 | H37: 800 | I37: 500 | J37: 500 | K37: 500 | L37: 500 | M37: 500 | N37: 500 | O37: =SUM(C37:N37) -> 7800
B38: Valla pequeña (desde M3) | C38: 0 | D38: 0 | E38: 350 | F38: 350 | G38: 350 | H38: 350 | I38: 350 | J38: 350 | K38: 350 | L38: 350 | M38: 350 | N38: 350 | O38: =SUM(C38:N38) -> 3500
B39: Material + transporte + contingencia (incl. buffer VE 20%) | C39: 1322 | D39: 1322 | E39: 1308 | F39: 1308 | G39: 1308 | H39: 1308 | I39: 1241 | J39: 1241 | K39: 1241 | L39: 1241 | M39: 1241 | N39: 1241 | O39: =SUM(C39:N39) -> 15322
B40: Total Costos | C40: =C28+C29+C30+C31+C32+C33+C34+C35+C36+C37+C38+C39 -> 8011 | D40: =D28+D29+D30+D31+D32+D33+D34+D35+D36+D37+D38+D39 -> 8011 | E40: =E28+E29+E30+E31+E32+E33+E34+E35+E36+E37+E38+E39 -> 8347 | F40: =F28+F29+F30+F31+F32+F33+F34+F35+F36+F37+F38+F39 -> 8347 | G40: =G28+G29+G30+G31+G32+G33+G34+G35+G36+G37+G38+G39 -> 8347 | H40: =H28+H29+H30+H31+H32+H33+H34+H35+H36+H37+H38+H39 -> 8347 | I40: =I28+I29+I30+I31+I32+I33+I34+I35+I36+I37+I38+I39 -> 7980 | J40: =J28+J29+J30+J31+J32+J33+J34+J35+J36+J37+J38+J39 -> 7980 | ... N40: =N28+N29+N30+N31+N32+N33+N34+N35+N36+N37+N38+N39 -> 7980 | O40: =SUM(C40:N40) -> 97290
B42: FCF | C42: =C25-C40 -> -6511 | D42: =D25-D40 -> -5843 | E42: =E25-E40 -> -5247 | F42: =F25-F40 -> -4647 | G42: =G25-G40 -> -4097 | H42: =H25-H40 -> -3497 | I42: =I25-I40 -> -2580 | J42: =J25-J40 -> -2030 | ... N42: =N25-N40 -> -30 | O42: =SUM(C42:N42) -> -37322
B43: FCF acumulado | C43: =C42 -> -6511 | D43: =C43+D42 -> -12354 | E43: =D43+E42 -> -17601 | F43: =E43+F42 -> -22248 | G43: =F43+G42 -> -26345 | H43: =G43+H42 -> -29842 | I43: =H43+I42 -> -32422 | J43: =I43+J42 -> -34452 | K43: =J43+K42 -> -35932 | ... N43: =M43+N42 -> -37322 | O43: =N43 -> -37322
B44: CCF (inversor SAFE 18,66%) | C44: =C42*$C$11 -> -1214.9526 | D44: =D42*$C$11 -> -1090.3038 | E44: =E42*$C$11 -> -979.0902 | F44: =F42*$C$11 -> -867.1302 | G44: =G42*$C$11 -> -764.5002 | H44: =H42*$C$11 -> -652.5402 | I44: =I42*$C$11 -> -481.428 | J44: =J42*$C$11 -> -378.798 | ... N44: =N42*$C$11 -> -5.598
...

Sheet Año 2
B2: ITEMS | C2: DATOS
B3: Farmacias activas cierre (ref.) | C3: ='Año 1'!N19 -> 159
B4: Revenue anual USD [LARGO PLAZO] | C4: 102000
B5: Costos anual USD [LARGO PLAZO] | C5: 96000
B6: Participación Inversor SAFE | C6: 0.1866
B7: Participación Founders | C7: =1-C6 -> 0.8134
B8: Etiqueta | C8: PROYECCION §2
B9: AÑO 2 | C9: AÑO 2
C10: Mes 1 | D10: Mes 2 | E10: Mes 3 | F10: Mes 4 | G10: Mes 5 | H10: Mes 6 | I10: Mes 7 | J10: Mes 8 | K10: Mes 9 | L10: Mes 10 | M10: Mes 11 | N10: Mes 12 | O10: TOTAL
B11: Farmacias activas promedio mes [LARGO PLAZO] | C11: 187 | D11: 187 | E11: 187 | F11: 187 | G11: 187 | H11: 187 | I11: 187 | J11: 187 | K11: 187 | L11: 187 | M11: 187 | N11: 187 | O11: =N11 -> 187
B13: Ingresos ($)
B14: Revenue plataforma | C14: 6667.17 | D14: 6667.17 | E14: 6667.17 | F14: 8046.58 | G14: 8046.58 | H14: 8046.58 | I14: 9196.09 | J14: 9196.09 | K14: 9196.09 | L14: 10090.16 | M14: 10090.16 | N14: 10090.16 | O14: =SUM(C14:N14) -> 102000
B15: Total Ingresos | C15: =C14 -> 6667.17 | D15: =D14 -> 6667.17 | E15: =E14 -> 6667.17 | F15: =F14 -> 8046.58 | G15: =G14 -> 8046.58 | H15: =H14 -> 8046.58 | I15: =I14 -> 9196.09 | J15: =J14 -> 9196.09 | ... N15: =N14 -> 10090.16 | O15: =SUM(C15:N15) -> 102000
B17: Costos ($)
B18: Equipo comercial + ops | C18: 2691.47 | D18: 2691.47 | E18: 2691.47 | F18: 2778.29 | G18: 2778.29 | H18: 2778.29 | I18: 2865.12 | J18: 2865.12 | K18: 2865.12 | L18: 2865.12 | M18: 2865.12 | N18: 2865.12 | O18: =SUM(C18:N18) -> 33600
B19: Marketing digital | C19: 1384.19 | D19: 1384.19 | E19: 1384.19 | F19: 1428.84 | G19: 1428.84 | H19: 1428.84 | I19: 1473.49 | J19: 1473.49 | K19: 1473.49 | L19: 1473.49 | M19: 1473.49 | N19: 1473.49 | O19: =SUM(C19:N19) -> 17280.03
B20: Hosting + SaaS | C20: 615.19 | D20: 615.19 | E20: 615.19 | F20: 635.04 | G20: 635.04 | H20: 635.04 | I20: 654.88 | J20: 654.88 | K20: 654.88 | L20: 654.88 | M20: 654.88 | N20: 654.88 | O20: =SUM(C20:N20) -> 7679.97
B21: Legal / contador | C21: 538.29 | D21: 538.29 | E21: 538.29 | F21: 555.66 | G21: 555.66 | H21: 555.66 | I21: 573.02 | J21: 573.02 | K21: 573.02 | L21: 573.02 | M21: 573.02 | N21: 573.02 | O21: =SUM(C21:N21) -> 6719.97
B22: HQ + servicios | C22: 922.79 | D22: 922.79 | E22: 922.79 | F22: 952.56 | G22: 952.56 | H22: 952.56 | I22: 982.33 | J22: 982.33 | K22: 982.33 | L22: 982.33 | M22: 982.33 | N22: 982.33 | O22: =SUM(C22:N22) -> 11520.03
B23: Imprevistos / buffer | C23: 1537.98 | D23: 1537.98 | E23: 1537.98 | F23: 1587.6 | G23: 1587.6 | H23: 1587.6 | I23: 1637.21 | J23: 1637.21 | K23: 1637.21 | L23: 1637.21 | M23: 1637.21 | N23: 1637.21 | O23: =SUM(C23:N23) -> 19200
B24: Total Costos | O24: =SUM(C18:N23) -> 96000
B26: FCF | C26: =C15-C24 -> 6667.17 | D26: =D15-D24 -> 6667.17 | E26: =E15-E24 -> 6667.17 | F26: =F15-F24 -> 8046.58 | G26: =G15-G24 -> 8046.58 | H26: =H15-H24 -> 8046.58 | I26: =I15-I24 -> 9196.09 | J26: =J15-J24 -> 9196.09 | ... N26: =N15-N24 -> 10090.16 | O26: =SUM(C26:N26) -> 102000
B27: FCF acumulado | C27: =C26 -> 6667.17 | D27: =C27+D26 -> 13334.34 | E27: =D27+E26 -> 20001.51 | F27: =E27+F26 -> 28048.09 | G27: =F27+G26 -> 36094.67 | H27: =G27+H26 -> 44141.25 | I27: =H27+I26 -> 53337.34 | J27: =I27+J26 -> 62533.43 | K27: =J27+K26 -> 71729.52 | ... N27: =M27+N26 -> 102000 | O27: =N27 -> 102000
B28: CCF (inversor SAFE 18,66%) | C28: =C26*$C$6 -> 1244.0939 | D28: =D26*$C$6 -> 1244.0939 | E28: =E26*$C$6 -> 1244.0939 | F28: =F26*$C$6 -> 1501.4918 | G28: =G26*$C$6 -> 1501.4918 | H28: =H26*$C$6 -> 1501.4918 | I28: =I26*$C$6 -> 1715.9904 | J28: =J26*$C$6 -> 1715.9904 | ... N28: =N26*$C$6 -> 1882.8239
B29: ECF (founders 81,34%) | C29: =C26-C28 -> 5423.0761 | D29: =D26-D28 -> 5423.0761 | E29: =E26-E28 -> 5423.0761 | F29: =F26-F28 -> 6545.0882 | G29: =G26-G28 -> 6545.0882 | H29: =H26-H28 -> 6545.0882 | I29: =I26-I28 -> 7480.0996 | J29: =J26-J28 -> 7480.0996 | ... N29: =N26-N28 -> 8207.3361

Sheet Año 3
B2: ITEMS | C2: DATOS
B3: Farmacias activas cierre (ref.) | C3: ='Año 2'!N11 -> 187
B4: Revenue anual USD [LARGO PLAZO] | C4: 192000
B5: Costos anual USD [LARGO PLAZO] | C5: 108000
B6: Participación Inversor SAFE | C6: 0.1866
B7: Participación Founders | C7: =1-C6 -> 0.8134
B8: Etiqueta | C8: PROYECCION §3
B9: AÑO 3 | C9: AÑO 3
C10: Mes 1 | D10: Mes 2 | E10: Mes 3 | F10: Mes 4 | G10: Mes 5 | H10: Mes 6 | I10: Mes 7 | J10: Mes 8 | K10: Mes 9 | L10: Mes 10 | M10: Mes 11 | N10: Mes 12 | O10: TOTAL
B11: Farmacias activas promedio mes [LARGO PLAZO] | C11: 374 | D11: 374 | E11: 374 | F11: 374 | G11: 374 | H11: 374 | I11: 374 | J11: 374 | K11: 374 | L11: 374 | M11: 374 | N11: 374 | O11: =N11 -> 374
B13: Ingresos ($)
B14: Revenue plataforma | C14: 12325.93 | D14: 12325.93 | E14: 12325.93 | F14: 14696.3 | G14: 14696.3 | H14: 14696.3 | I14: 17066.67 | J14: 17066.67 | K14: 17066.67 | L14: 19911.11 | M14: 19911.11 | N14: 19911.11 | O14: =SUM(C14:N14) -> 192000.03
B15: Total Ingresos | C15: =C14 -> 12325.93 | D15: =D14 -> 12325.93 | E15: =E14 -> 12325.93 | F15: =F14 -> 14696.3 | G15: =G14 -> 14696.3 | H15: =H14 -> 14696.3 | I15: =I14 -> 17066.67 | J15: =J14 -> 17066.67 | ... N15: =N14 -> 19911.11 | O15: =SUM(C15:N15) -> 192000.03
B17: Costos ($)
B18: Equipo comercial + ops | C18: 2625 | D18: 2625 | E18: 2625 | F18: 2975 | G18: 2975 | H18: 2975 | I18: 3325 | J18: 3325 | K18: 3325 | L18: 3675 | M18: 3675 | N18: 3675 | O18: =SUM(C18:N18) -> 37800
B19: Marketing digital | C19: 1350 | D19: 1350 | E19: 1350 | F19: 1530 | G19: 1530 | H19: 1530 | I19: 1710 | J19: 1710 | K19: 1710 | L19: 1890 | M19: 1890 | N19: 1890 | O19: =SUM(C19:N19) -> 19440
B20: Hosting + SaaS | C20: 600 | D20: 600 | E20: 600 | F20: 680 | G20: 680 | H20: 680 | I20: 760 | J20: 760 | K20: 760 | L20: 840 | M20: 840 | N20: 840 | O20: =SUM(C20:N20) -> 8640
B21: Legal / contador | C21: 525 | D21: 525 | E21: 525 | F21: 595 | G21: 595 | H21: 595 | I21: 665 | J21: 665 | K21: 665 | L21: 735 | M21: 735 | N21: 735 | O21: =SUM(C21:N21) -> 7560
B22: HQ + servicios | C22: 900 | D22: 900 | E22: 900 | F22: 1020 | G22: 1020 | H22: 1020 | I22: 1140 | J22: 1140 | K22: 1140 | L22: 1260 | M22: 1260 | N22: 1260 | O22: =SUM(C22:N22) -> 12960
B23: Imprevistos / buffer | C23: 1500 | D23: 1500 | E23: 1500 | F23: 1700 | G23: 1700 | H23: 1700 | I23: 1900 | J23: 1900 | K23: 1900 | L23: 2100 | M23: 2100 | N23: 2100 | O23: =SUM(C23:N23) -> 21600
B24: Total Costos | O24: =SUM(C18:N23) -> 108000
B26: FCF | C26: =C15-C24 -> 12325.93 | D26: =D15-D24 -> 12325.93 | E26: =E15-E24 -> 12325.93 | F26: =F15-F24 -> 14696.3 | G26: =G15-G24 -> 14696.3 | H26: =H15-H24 -> 14696.3 | I26: =I15-I24 -> 17066.67 | J26: =J15-J24 -> 17066.67 | ... N26: =N15-N24 -> 19911.11 | O26: =SUM(C26:N26) -> 192000.03
B27: FCF acumulado | C27: =C26 -> 12325.93 | D27: =C27+D26 -> 24651.86 | E27: =D27+E26 -> 36977.79 | F27: =E27+F26 -> 51674.09 | G27: =F27+G26 -> 66370.39 | H27: =G27+H26 -> 81066.69 | I27: =H27+I26 -> 98133.36 | J27: =I27+J26 -> 115200.03 | K27: =J27+K26 -> 132266.7 | ... N27: =M27+N26 -> 192000.03 | O27: =N27 -> 192000.03
B28: CCF (inversor SAFE 18,66%) | C28: =C26*$C$6 -> 2300.0185 | D28: =D26*$C$6 -> 2300.0185 | E28: =E26*$C$6 -> 2300.0185 | F28: =F26*$C$6 -> 2742.3296 | G28: =G26*$C$6 -> 2742.3296 | H28: =H26*$C$6 -> 2742.3296 | I28: =I26*$C$6 -> 3184.6406 | J28: =J26*$C$6 -> 3184.6406 | ... N28: =N26*$C$6 -> 3715.4131
B29: ECF (founders 81,34%) | C29: =C26-C28 -> 10025.911 | D29: =D26-D28 -> 10025.911 | E29: =E26-E28 -> 10025.911 | F29: =F26-F28 -> 11953.97 | G29: =G26-G28 -> 11953.97 | H29: =H26-H28 -> 11953.97 | I29: =I26-I28 -> 13882.029 | J29: =J26-J28 -> 13882.029 | ... N29: =N26-N28 -> 16195.697

Sheet Año 4
B2: ITEMS | C2: DATOS
B3: Farmacias activas cierre (ref.) | C3: ='Año 3'!N11 -> 374
B4: Revenue anual USD [LARGO PLAZO] | C4: 240000
B5: Costos anual USD [LARGO PLAZO] | C5: 130000
B6: Participación Inversor SAFE | C6: 0.1866
B7: Participación Founders | C7: =1-C6 -> 0.8134
B8: Etiqueta | C8: SUPUESTO MODELO
B9: AÑO 4 | C9: AÑO 4
C10: Mes 1 | D10: Mes 2 | E10: Mes 3 | F10: Mes 4 | G10: Mes 5 | H10: Mes 6 | I10: Mes 7 | J10: Mes 8 | K10: Mes 9 | L10: Mes 10 | M10: Mes 11 | N10: Mes 12 | O10: TOTAL
B11: Farmacias activas promedio mes [LARGO PLAZO] | C11: 442 | D11: 442 | E11: 442 | F11: 442 | G11: 442 | H11: 442 | I11: 442 | J11: 442 | K11: 442 | L11: 442 | M11: 442 | N11: 442 | O11: =N11 -> 442
B13: Ingresos ($)
B14: Revenue plataforma | C14: 20000 | D14: 20000 | E14: 20000 | F14: 20000 | G14: 20000 | H14: 20000 | I14: 20000 | J14: 20000 | K14: 20000 | L14: 20000 | M14: 20000 | N14: 20000 | O14: =SUM(C14:N14) -> 240000
B15: Total Ingresos | C15: =C14 -> 20000 | D15: =D14 -> 20000 | E15: =E14 -> 20000 | F15: =F14 -> 20000 | G15: =G14 -> 20000 | H15: =H14 -> 20000 | I15: =I14 -> 20000 | J15: =J14 -> 20000 | ... N15: =N14 -> 20000 | O15: =SUM(C15:N15) -> 240000
B17: Costos ($)
B18: Equipo comercial + ops | C18: 3791.67 | D18: 3791.67 | E18: 3791.67 | F18: 3791.67 | G18: 3791.67 | H18: 3791.67 | I18: 3791.67 | J18: 3791.67 | K18: 3791.67 | L18: 3791.67 | M18: 3791.67 | N18: 3791.67 | O18: =SUM(C18:N18) -> 45500.04
B19: Marketing digital | C19: 1950 | D19: 1950 | E19: 1950 | F19: 1950 | G19: 1950 | H19: 1950 | I19: 1950 | J19: 1950 | K19: 1950 | L19: 1950 | M19: 1950 | N19: 1950 | O19: =SUM(C19:N19) -> 23400
B20: Hosting + SaaS | C20: 866.67 | D20: 866.67 | E20: 866.67 | F20: 866.67 | G20: 866.67 | H20: 866.67 | I20: 866.67 | J20: 866.67 | K20: 866.67 | L20: 866.67 | M20: 866.67 | N20: 866.67 | O20: =SUM(C20:N20) -> 10400.04
B21: Legal / contador | C21: 758.33 | D21: 758.33 | E21: 758.33 | F21: 758.33 | G21: 758.33 | H21: 758.33 | I21: 758.33 | J21: 758.33 | K21: 758.33 | L21: 758.33 | M21: 758.33 | N21: 758.33 | O21: =SUM(C21:N21) -> 9099.96
B22: HQ + servicios | C22: 1300 | D22: 1300 | E22: 1300 | F22: 1300 | G22: 1300 | H22: 1300 | I22: 1300 | J22: 1300 | K22: 1300 | L22: 1300 | M22: 1300 | N22: 1300 | O22: =SUM(C22:N22) -> 15600
B23: Imprevistos / buffer | C23: 2166.67 | D23: 2166.67 | E23: 2166.67 | F23: 2166.67 | G23: 2166.67 | H23: 2166.67 | I23: 2166.67 | J23: 2166.67 | K23: 2166.67 | L23: 2166.67 | M23: 2166.67 | N23: 2166.67 | O23: =SUM(C23:N23) -> 26000.04
B24: Total Costos | O24: =SUM(C18:N23) -> 130000.08
B26: FCF | C26: =C15-C24 -> 20000 | D26: =D15-D24 -> 20000 | E26: =E15-E24 -> 20000 | F26: =F15-F24 -> 20000 | G26: =G15-G24 -> 20000 | H26: =H15-H24 -> 20000 | I26: =I15-I24 -> 20000 | J26: =J15-J24 -> 20000 | ... N26: =N15-N24 -> 20000 | O26: =SUM(C26:N26) -> 240000
B27: FCF acumulado | C27: =C26 -> 20000 | D27: =C27+D26 -> 40000 | E27: =D27+E26 -> 60000 | F27: =E27+F26 -> 80000 | G27: =F27+G26 -> 100000 | H27: =G27+H26 -> 120000 | I27: =H27+I26 -> 140000 | J27: =I27+J26 -> 160000 | K27: =J27+K26 -> 180000 | ... N27: =M27+N26 -> 240000 | O27: =N27 -> 240000
B28: CCF (inversor SAFE 18,66%) | C28: =C26*$C$6 -> 3732 | D28: =D26*$C$6 -> 3732 | E28: =E26*$C$6 -> 3732 | F28: =F26*$C$6 -> 3732 | G28: =G26*$C$6 -> 3732 | H28: =H26*$C$6 -> 3732 | I28: =I26*$C$6 -> 3732 | J28: =J26*$C$6 -> 3732 | ... N28: =N26*$C$6 -> 3732
B29: ECF (founders 81,34%) | C29: =C26-C28 -> 16268 | D29: =D26-D28 -> 16268 | E29: =E26-E28 -> 16268 | F29: =F26-F28 -> 16268 | G29: =G26-G28 -> 16268 | H29: =H26-H28 -> 16268 | I29: =I26-I28 -> 16268 | J29: =J26-J28 -> 16268 | ... N29: =N26-N28 -> 16268

Sheet Año 5
B2: ITEMS | C2: DATOS
B3: Farmacias activas cierre (ref.) | C3: ='Año 4'!N11 -> 442
B4: Revenue anual USD [LARGO PLAZO] | C4: 300000
B5: Costos anual USD [LARGO PLAZO] | C5: 150000
B6: Participación Inversor SAFE | C6: 0.1866
B7: Participación Founders | C7: =1-C6 -> 0.8134
B8: Etiqueta | C8: SUPUESTO MODELO
B9: AÑO 5 | C9: AÑO 5
C10: Mes 1 | D10: Mes 2 | E10: Mes 3 | F10: Mes 4 | G10: Mes 5 | H10: Mes 6 | I10: Mes 7 | J10: Mes 8 | K10: Mes 9 | L10: Mes 10 | M10: Mes 11 | N10: Mes 12 | O10: TOTAL
B11: Farmacias activas promedio mes [LARGO PLAZO] | C11: 510 | D11: 510 | E11: 510 | F11: 510 | G11: 510 | H11: 510 | I11: 510 | J11: 510 | K11: 510 | L11: 510 | M11: 510 | N11: 510 | O11: =N11 -> 510
B13: Ingresos ($)
B14: Revenue plataforma | C14: 25000 | D14: 25000 | E14: 25000 | F14: 25000 | G14: 25000 | H14: 25000 | I14: 25000 | J14: 25000 | K14: 25000 | L14: 25000 | M14: 25000 | N14: 25000 | O14: =SUM(C14:N14) -> 300000
B15: Total Ingresos | C15: =C14 -> 25000 | D15: =D14 -> 25000 | E15: =E14 -> 25000 | F15: =F14 -> 25000 | G15: =G14 -> 25000 | H15: =H14 -> 25000 | I15: =I14 -> 25000 | J15: =J14 -> 25000 | ... N15: =N14 -> 25000 | O15: =SUM(C15:N15) -> 300000
B17: Costos ($)
B18: Equipo comercial + ops | C18: 4375 | D18: 4375 | E18: 4375 | F18: 4375 | G18: 4375 | H18: 4375 | I18: 4375 | J18: 4375 | K18: 4375 | L18: 4375 | M18: 4375 | N18: 4375 | O18: =SUM(C18:N18) -> 52500
B19: Marketing digital | C19: 2250 | D19: 2250 | E19: 2250 | F19: 2250 | G19: 2250 | H19: 2250 | I19: 2250 | J19: 2250 | K19: 2250 | L19: 2250 | M19: 2250 | N19: 2250 | O19: =SUM(C19:N19) -> 27000
B20: Hosting + SaaS | C20: 1000 | D20: 1000 | E20: 1000 | F20: 1000 | G20: 1000 | H20: 1000 | I20: 1000 | J20: 1000 | K20: 1000 | L20: 1000 | M20: 1000 | N20: 1000 | O20: =SUM(C20:N20) -> 12000
B21: Legal / contador | C21: 875 | D21: 875 | E21: 875 | F21: 875 | G21: 875 | H21: 875 | I21: 875 | J21: 875 | K21: 875 | L21: 875 | M21: 875 | N21: 875 | O21: =SUM(C21:N21) -> 10500
B22: HQ + servicios | C22: 1500 | D22: 1500 | E22: 1500 | F22: 1500 | G22: 1500 | H22: 1500 | I22: 1500 | J22: 1500 | K22: 1500 | L22: 1500 | M22: 1500 | N22: 1500 | O22: =SUM(C22:N22) -> 18000
B23: Imprevistos / buffer | C23: 2500 | D23: 2500 | E23: 2500 | F23: 2500 | G23: 2500 | H23: 2500 | I23: 2500 | J23: 2500 | K23: 2500 | L23: 2500 | M23: 2500 | N23: 2500 | O23: =SUM(C23:N23) -> 30000
B24: Total Costos | O24: =SUM(C18:N23) -> 150000
B26: FCF | C26: =C15-C24 -> 25000 | D26: =D15-D24 -> 25000 | E26: =E15-E24 -> 25000 | F26: =F15-F24 -> 25000 | G26: =G15-G24 -> 25000 | H26: =H15-H24 -> 25000 | I26: =I15-I24 -> 25000 | J26: =J15-J24 -> 25000 | ... N26: =N15-N24 -> 25000 | O26: =SUM(C26:N26) -> 300000
B27: FCF acumulado | C27: =C26 -> 25000 | D27: =C27+D26 -> 50000 | E27: =D27+E26 -> 75000 | F27: =E27+F26 -> 100000 | G27: =F27+G26 -> 125000 | H27: =G27+H26 -> 150000 | I27: =H27+I26 -> 175000 | J27: =I27+J26 -> 200000 | K27: =J27+K26 -> 225000 | ... N27: =M27+N26 -> 300000 | O27: =N27 -> 300000
B28: CCF (inversor SAFE 18,66%) | C28: =C26*$C$6 -> 4665 | D28: =D26*$C$6 -> 4665 | E28: =E26*$C$6 -> 4665 | F28: =F26*$C$6 -> 4665 | G28: =G26*$C$6 -> 4665 | H28: =H26*$C$6 -> 4665 | I28: =I26*$C$6 -> 4665 | J28: =J26*$C$6 -> 4665 | ... N28: =N26*$C$6 -> 4665
B29: ECF (founders 81,34%) | C29: =C26-C28 -> 20335 | D29: =D26-D28 -> 20335 | E29: =E26-E28 -> 20335 | F29: =F26-F28 -> 20335 | G29: =G26-G28 -> 20335 | H29: =H26-H28 -> 20335 | I29: =I26-I28 -> 20335 | J29: =J26-J28 -> 20335 | ... N29: =N26-N28 -> 20335

Sheet Flujo Total
B2: PREMISAS DEL PROYECTO E INDICADORES — Zonix Pharma
B4: ITEMS | C4: DATOS
B5: ARPF placeholder USD/mes | C5: 50
B6: Participación Inversor SAFE | C6: 0.1866
B7: Participación Founders | C7: =1-C6 -> 0.8134
B8: Tasa Descuento | C8: 0.25
B9: Inversión Inicial (wire T+0) | C9: -111988
B10: SAFE post-money cap Lean | C10: 600000
B11: Nota reparto | C11: Ilustrativo — no sustituye term sheet SAFE
B16: Concepto | D16: Año 1 | E16: Año 2 | F16: Año 3 | G16: Año 4 | H16: Año 5 | I16: TOTAL
B17: Farmacias activas cierre | D17: ='Año 1'!N19 -> 159 | E17: ='Año 2'!N11 -> 187 | F17: ='Año 3'!N11 -> 374 | G17: ='Año 4'!N11 -> 442 | H17: ='Año 5'!N11 -> 510
B18: Total Ingresos anual | D18: ='Año 1'!O25 -> 59968 | E18: ='Año 2'!O15 -> 102000 | F18: ='Año 3'!O15 -> 192000.03 | G18: ='Año 4'!O15 -> 240000 | H18: ='Año 5'!O15 -> 300000 | I18: =SUM(D18:H18) -> 893968.03
B19: Total Costos anual | D19: ='Año 1'!O40 -> 97290 | E19: ='Año 2'!O24 -> 96000 | F19: ='Año 3'!O24 -> 108000 | G19: ='Año 4'!O24 -> 130000.08 | H19: ='Año 5'!O24 -> 150000 | I19: =SUM(D19:H19) -> 581290.08
B20: FCF anual | D20: =D18-D19 -> -37322 | E20: =E18-E19 -> 6000 | F20: =F18-F19 -> 84000.03 | G20: =G18-G19 -> 109999.92 | H20: =H18-H19 -> 150000 | I20: =SUM(D20:H20) -> 312677.95
B21: FCF acumulado | D21: =D20 -> -37322 | E21: =D21+E20 -> -31322 | F21: =E21+F20 -> 52678.03 | G21: =F21+G20 -> 162677.95 | H21: =G21+H20 -> 312677.95
B22: CCF (inversor SAFE) | D22: =D20*$C$6 -> -6964.2852 | E22: =E20*$C$6 -> 1119.6 | F22: =F20*$C$6 -> 15674.406 | G22: =G20*$C$6 -> 20525.985 | H22: =H20*$C$6 -> 27990 | K22: CCF acum Y5 | L22: Por recuperar Y5
B23: CCF acumulado (inversor) | D23: =D22 -> -6964.2852 | E23: =D23+E22 -> -5844.6852 | F23: =E23+F22 -> 9829.7204 | G23: =F23+G22 -> 30355.705 | H23: =G23+H22 -> 58345.705 | K23: =H23 -> 58345.705
B24: Por recuperar inversor (SAFE) | D24: =MAX(0,-$C$9-D23) -> 118952.29 | E24: =MAX(0,-$C$9-E23) -> 117832.69 | F24: =MAX(0,-$C$9-F23) -> 102158.28 | G24: =MAX(0,-$C$9-G23) -> 81632.295 | H24: =MAX(0,-$C$9-H23) -> 53642.295 | L24: =H24 -> 53642.295
B25: ECF (founders) | D25: =D20-D22 -> -30357.715 | E25: =E20-E22 -> 4880.4 | F25: =F20-F22 -> 68325.624 | G25: =G20-G22 -> 89473.935 | H25: =H20-H22 -> 122010
J27: Flujo IRR
J28: -111988
J29: =D20 -> -37322
J30: =E20 -> 6000
J31: =F20 -> 84000.03
J32: =G20 -> 109999.92
J33: =H20 -> 150000
B34: VP Flujos(5) | C34: =NPV($C$8,D20:H20) -> 111198.38
B35: VAN(5) | C35: =C34+C9 -> -789.61741
B36: VP Flujos(3) | C36: =NPV($C$8,D20:F20) -> 16990.415
B37: VAN(3) | C37: =C36+C9 -> -94997.585
B38: TIR(5) | C38: =IRR(J28:J33) -> 0.24815491
B39: TIR(3) | C39: =IRR(J28:J31) -> -0.17266745
B40: Tasa Requerida (r) | C40: =$C$8 -> 0.25
B41: Payback inversor (años, ilustrativo) | C41: =IF(H23>=ABS($C$9),5,IF(G23>=ABS($C$9),4,IF(F23>=ABS($C$9),3,IF(E23>=ABS($C$9),2,IF(D23>=ABS($C$9),1,"[LARGO PLAZO]"))))) -> [LARGO PLAZO]
B42: % SAFE recuperado (CCF acum Y5, ilustrativo) | C42: =H23/ABS($C$9) -> 0.52099962
B43: Lectura payback | C43: =IF(C41="[LARGO PLAZO]","CCF acum Y5 no cubre SAFE — ver % recuperado","") -> CCF acum Y5 no cubre SAFE — ver % recuperado
B45: NOTA: Reparto CCF/ECF ilustrativo post-cap SAFE 18,66%. No cláusula de dividendos.

Sheet Tasa Crecimiento
B2: TASAS DE CRECIMIENTO — Zonix Pharma
C4: Año 1 | D4: Año 2 | E4: Año 3 | F4: Año 4 | G4: Año 5
B6: Revenue anual % vs año anterior | D6: =IF(C8=0,"",(D8-C8)/C8) -> 0.70090715 | E6: =IF(D8=0,"",(E8-D8)/D8) -> 0.88235324 | F6: =IF(E8=0,"",(F8-E8)/E8) -> 0.2499998 | G6: =IF(F8=0,"",(G8-F8)/F8) -> 0.25
B7: Farmacias activas cierre | C7: ='Año 1'!N19 -> 159 | D7: ='Año 2'!N11 -> 187 | E7: ='Año 3'!N11 -> 374 | F7: ='Año 4'!N11 -> 442 | G7: ='Año 5'!N11 -> 510
B8: Revenue anual USD | C8: ='Año 1'!O25 -> 59968 | D8: ='Año 2'!O15 -> 102000 | E8: ='Año 3'!O15 -> 192000.03 | F8: ='Año 4'!O15 -> 240000 | G8: ='Año 5'!O15 -> 300000
B9: ARPF placeholder USD | C9: 50 | D9: 52 | E9: 55 | F9: 58 | G9: 60
B10: Burn prom. mensual USD | C10: ='Año 1'!O40/12 -> 8107.5 | D10: ='Año 2'!O24/12 -> 8000 | E10: ='Año 3'!O24/12 -> 9000 | F10: ='Año 4'!O24/12 -> 10833.34 | G10: ='Año 5'!O24/12 -> 12500
B11: Etiqueta | C11: ancla | D11: PROY §2 | E11: PROY §3 | F11: SUPUESTO | G11: SUPUESTO
